

// 1.调用abort()
```cpp
cout << "start" << endl;
  abort(); // 直接中断程序
  cout << "end" << endl; 
```

// 2. 返回错误码
```cpp
bool divide(int n,int m,int *result){
    if(m=0){
        return false;
    }
    *result=n/m;
    return true;
}
````

// 3.异常机制（通常用于类）
```cpp
int i = 10;
double divide(int n, int m) {
  if (m == 0) {
    throw i; // throw后面跟着的表达式的值类型将会像函数调用一样，当做实参传递到匹配的catch()函数中去，记住，这里的传递是值传递，会发生拷贝，尽管有时候会有catch(&)的出现，但那只是为了兼容派生类，当然，真到派生类时，要把catch(base&)放到最后。
  }
  int di;
  di = n / m;
  return di;
}
int main() {
  cout << "start------" << endl;
  try {
    divide(1, 0);
  } catch (const char *s) { // 匹配常量字符串的，例如throw "";
    cout << "call char * bad!" << endl;
    cout << s << endl;
  } catch (int i) { // 匹配int的，例如throw i;
    cout << "call int bad!" << endl;
    cout << i << endl;
  }
  cout << "end--------" << endl; // catch并不会中断程序
}
```
(1)当throw引发异常，而又没有try模块，或者没有匹配的catch()，那么程序会调用abort()来终止。

// 4.将对象用作异常类型(能传递的信息多，可以使用不同的异常类型来区分不同函数在不同情况下引发的不同异常)
```cpp
class err{
private:
    string str;
public:
    err(string str);
    void mesg();
}

double divide(int n, int m) {
  if (m == 0) {
    throw err("m can no zero!"); 
  }
  int di;
  di = n / m;
  return di;
}
int main() {
  cout << "start------" << endl;
  try {
    divide(1, 0);
  } catch (err &er) { // 匹配err类;
    cout << "call char * bad!" << endl;
    cout << s << endl;
  }
  cout << "end--------" << endl; 
}
```

// 关键字noexcept
```cpp
void printt() noexcept; // 程序员承诺该函数不会引起异常，编译器会对其跳过相应的检测
void printt() noexcept(bool); // 还可以在其中放入bool表达式，只有该表达式为false才会抛出异常
// 还会存在比较老的异常规范throw(),不推荐使用
void printt() throw();
```

// 栈解退
<div align="center">

![images](../images/throw的程序流程(栈解退).jpg)
</div>
```cpp
// 栈解退的这种机制，也会自动清除中间调用的类对象，使其调用析构函数
```

// c++提供的异常的原始基类exception类
```cpp
double divide(int n, int m) {
  if (m == 0) {
    throw excption("m can no zero!"); 
  }
  int di;
  di = n / m;
  return di;
}
int main() {
  cout << "start------" << endl;
  try
  {
   divide(2,0);
  }
  catch(const std::exception& e)
  {
    std::cerr << e.what() << '\n';
  }
  cout << "end--------" << endl; 
}

class errr:public excpetion{
public:
    const char* what(){return "......";} // 重写what()虚成员函数，，显示自己的提示字符
}
int main(){
try{
    // ......
}catch(std::excpetion &e){ // 可以使用excpetion基类统一捕获异常
    std::cerr << e.what() << '\n';
    // ......
}
}

// 其他官方提供的，基于excpetion的异常类
    // 1.stdexcpetion异常类
        // 都是以logic_err(逻辑错误)为基类:
        domain_error; // 作用域错误，一般是超出作用域的错误警告
        invalid_argument; // 无效参数
        length_error; // 内存长度错误
        out_of_dounds; // 使用数组时的索引错误
        // 都是以runtime_error(运行时错误)为基类:
        range_error; // 范围迭代器错误
        overflow_error; // 溢出错误，是指整数或者浮点数超出最大限制
        underflow_error; // 下溢错误，与overflow相反，是小到无法表示
    // 2.bad_alloc坏的内存分配（专用于new导致的内存分配问题，头文件new中有其声明）
    try{
        int *i=new int;
    }catch(std::bad_alloc &ba){
    std::cerr << ba.what() << '\n';
    exit(EXIT_FAILURE); // 终止退出程序，这是比较暴力的终止，不会调用析构函数
    }
    int *i=new(nothrow) int // 此时如果失败，那将返回空指针，而不会中断程序。
```

// RTTI(runtime type identification)运行阶段类型识别，只能在含有虚函数的类中使用
```cpp

```